<?xml version="1.0" encoding="utf-8"?>
<!-- This URDF was automatically created by SolidWorks to URDF Exporter! Originally created by Stephen Brawner (brawner@gmail.com) 
     Commit Version: 1.6.0-4-g7f85cfe  Build Version: 1.6.7995.38578
     For more information, please see http://wiki.ros.org/sw_urdf_exporter -->
<robot
  name="Assem1">
  <link
    name="base_link">
    <inertial>
      <origin
        xyz="-0.472647441390191 0.0789496187119673 -0.0328685285624268"
        rpy="0 0 0" />
      <mass
        value="0.422184039657028" />
      <inertia
        ixx="0.000320826217154303"
        ixy="4.20879745539875E-05"
        ixz="7.16279846938345E-05"
        iyy="0.00561040931161564"
        iyz="-1.07433119929774E-06"
        izz="0.00533913204176968" />
    </inertial>
    <visual>
      <origin
        xyz="0 0 0"
        rpy="0 0 0" />
      <geometry>
        <mesh
          filename="package://Assem1/meshes/base_link.STL" />
      </geometry>
      <material
        name="">
        <color
          rgba="1 1 1 1" />
      </material>
    </visual>
    <collision>
      <origin
        xyz="0 0 0"
        rpy="0 0 0" />
      <geometry>
        <mesh
          filename="package://Assem1/meshes/base_link.STL" />
      </geometry>
    </collision>
  </link>
  <link
    name="Chassis_Link">
    <inertial>
      <origin
        xyz="-0.472647441390191 0.0789496187119673 -0.0328685285624268"
        rpy="0 0 0" />
      <mass
        value="0.422184039657028" />
      <inertia
        ixx="0.000320826217154303"
        ixy="4.20879745539875E-05"
        ixz="7.16279846938345E-05"
        iyy="0.00561040931161564"
        iyz="-1.07433119929774E-06"
        izz="0.00533913204176968" />
    </inertial>
    <visual>
      <origin
        xyz="0 0 0"
        rpy="0 0 0" />
      <geometry>
        <mesh
          filename="package://Assem1/meshes/Chassis_Link.STL" />
      </geometry>
      <material
        name="">
        <color
          rgba="1 1 1 1" />
      </material>
    </visual>
    <collision>
      <origin
        xyz="0 0 0"
        rpy="0 0 0" />
      <geometry>
        <mesh
          filename="package://Assem1/meshes/Chassis_Link.STL" />
      </geometry>
    </collision>
  </link>
  <joint
    name="Chassis_Joint"
    type="fixed">
    <origin
      xyz="-0.060804 -0.021978 0.029871"
      rpy="3.1416 0 0" />
    <parent
      link="base_link" />
    <child
      link="Chassis_Link" />
    <axis
      xyz="0 0 0" />
  </joint>
  <link
    name="Cabin_Link">
    <inertial>
      <origin
        xyz="-0.472647441390191 0.0789496187119673 -0.0328685285624268"
        rpy="0 0 0" />
      <mass
        value="0.422184039657028" />
      <inertia
        ixx="0.000320826217154303"
        ixy="4.20879745539875E-05"
        ixz="7.16279846938345E-05"
        iyy="0.00561040931161564"
        iyz="-1.07433119929774E-06"
        izz="0.00533913204176968" />
    </inertial>
    <visual>
      <origin
        xyz="0 0 0"
        rpy="0 0 0" />
      <geometry>
        <mesh
          filename="package://Assem1/meshes/Cabin_Link.STL" />
      </geometry>
      <material
        name="">
        <color
          rgba="1 1 1 1" />
      </material>
    </visual>
    <collision>
      <origin
        xyz="0 0 0"
        rpy="0 0 0" />
      <geometry>
        <mesh
          filename="package://Assem1/meshes/Cabin_Link.STL" />
      </geometry>
    </collision>
  </link>
  <joint
    name="Cabin_Joint"
    type="fixed">
    <origin
      xyz="0.4575 -0.065 0.047"
      rpy="0 1.5708 0" />
    <parent
      link="Chassis_Link" />
    <child
      link="Cabin_Link" />
    <axis
      xyz="0 0 0" />
  </joint>
  <link
    name="Front_Link">
    <inertial>
      <origin
        xyz="-0.472647441390191 0.0789496187119673 -0.0328685285624268"
        rpy="0 0 0" />
      <mass
        value="0.422184039657028" />
      <inertia
        ixx="0.000320826217154303"
        ixy="4.20879745539875E-05"
        ixz="7.16279846938345E-05"
        iyy="0.00561040931161564"
        iyz="-1.07433119929774E-06"
        izz="0.00533913204176968" />
    </inertial>
    <visual>
      <origin
        xyz="0 0 0"
        rpy="0 0 0" />
      <geometry>
        <mesh
          filename="package://Assem1/meshes/Front_Link.STL" />
      </geometry>
      <material
        name="">
        <color
          rgba="0.647058823529412 0.619607843137255 0.588235294117647 1" />
      </material>
    </visual>
    <collision>
      <origin
        xyz="0 0 0"
        rpy="0 0 0" />
      <geometry>
        <mesh
          filename="package://Assem1/meshes/Front_Link.STL" />
      </geometry>
    </collision>
  </link>
  <joint
    name="Front_Joint"
    type="fixed">
    <origin
      xyz="0.285 -0.044 0.008"
      rpy="3.1416 -1.5708 0" />
    <parent
      link="Chassis_Link" />
    <child
      link="Front_Link" />
    <axis
      xyz="0 0 0" />
  </joint>
  <link
    name="Front_Wheel_Link">
    <inertial>
      <origin
        xyz="-0.472647441390191 0.0789496187119673 -0.0328685285624268"
        rpy="0 0 0" />
      <mass
        value="0.422184039657028" />
      <inertia
        ixx="0.000320826217154303"
        ixy="4.20879745539875E-05"
        ixz="7.16279846938345E-05"
        iyy="0.00561040931161564"
        iyz="-1.07433119929774E-06"
        izz="0.00533913204176968" />
    </inertial>
    <visual>
      <origin
        xyz="0 0 0"
        rpy="0 0 0" />
      <geometry>
        <mesh
          filename="package://Assem1/meshes/Front_Wheel_Link.STL" />
      </geometry>
      <material
        name="">
        <color
          rgba="0.792156862745098 0.819607843137255 0.933333333333333 1" />
      </material>
    </visual>
    <collision>
      <origin
        xyz="0 0 0"
        rpy="0 0 0" />
      <geometry>
        <mesh
          filename="package://Assem1/meshes/Front_Wheel_Link.STL" />
      </geometry>
    </collision>
  </link>
  <joint
    name="Front_Wheel_Joint"
    type="continuous">
    <origin
      xyz="-0.20525 -0.054331 -0.040912"
      rpy="2.2065 0.26123 1.7591" />
    <parent
      link="Front_Link" />
    <child
      link="Front_Wheel_Link" />
    <axis
      xyz="0 0 0" />
  </joint>
  <link
    name="Rear_Link">
    <inertial>
      <origin
        xyz="-0.472647441390191 0.0789496187119673 -0.0328685285624268"
        rpy="0 0 0" />
      <mass
        value="0.422184039657028" />
      <inertia
        ixx="0.000320826217154303"
        ixy="4.20879745539875E-05"
        ixz="7.16279846938345E-05"
        iyy="0.00561040931161564"
        iyz="-1.07433119929774E-06"
        izz="0.00533913204176968" />
    </inertial>
    <visual>
      <origin
        xyz="0 0 0"
        rpy="0 0 0" />
      <geometry>
        <mesh
          filename="package://Assem1/meshes/Rear_Link.STL" />
      </geometry>
      <material
        name="">
        <color
          rgba="0.792156862745098 0.819607843137255 0.933333333333333 1" />
      </material>
    </visual>
    <collision>
      <origin
        xyz="0 0 0"
        rpy="0 0 0" />
      <geometry>
        <mesh
          filename="package://Assem1/meshes/Rear_Link.STL" />
      </geometry>
    </collision>
  </link>
  <joint
    name="Rear_Joint"
    type="fixed">
    <origin
      xyz="0.09 -0.082463 -0.079"
      rpy="3.1416 0 3.1416" />
    <parent
      link="Chassis_Link" />
    <child
      link="Rear_Link" />
    <axis
      xyz="0 0 0" />
  </joint>
  <link
    name="Rear_Wheel_Link">
    <inertial>
      <origin
        xyz="-0.472647441390191 0.0789496187119673 -0.0328685285624268"
        rpy="0 0 0" />
      <mass
        value="0.422184039657028" />
      <inertia
        ixx="0.000320826217154303"
        ixy="4.20879745539875E-05"
        ixz="7.16279846938345E-05"
        iyy="0.00561040931161564"
        iyz="-1.07433119929774E-06"
        izz="0.00533913204176968" />
    </inertial>
    <visual>
      <origin
        xyz="0 0 0"
        rpy="0 0 0" />
      <geometry>
        <mesh
          filename="package://Assem1/meshes/Rear_Wheel_Link.STL" />
      </geometry>
      <material
        name="">
        <color
          rgba="0.792156862745098 0.819607843137255 0.933333333333333 1" />
      </material>
    </visual>
    <collision>
      <origin
        xyz="0 0 0"
        rpy="0 0 0" />
      <geometry>
        <mesh
          filename="package://Assem1/meshes/Rear_Wheel_Link.STL" />
      </geometry>
    </collision>
  </link>
  <joint
    name="Rear_Wheel_Joint"
    type="continuous">
    <origin
      xyz="0 0 0"
      rpy="-3.1416 0 -2.7398" />
    <parent
      link="Rear_Link" />
    <child
      link="Rear_Wheel_Link" />
    <axis
      xyz="0 0 1" />
  </joint>
  <link
    name="Trunk_Link">
    <inertial>
      <origin
        xyz="-0.472647441390191 0.0789496187119673 -0.0328685285624268"
        rpy="0 0 0" />
      <mass
        value="0.422184039657028" />
      <inertia
        ixx="0.000320826217154303"
        ixy="4.20879745539875E-05"
        ixz="7.16279846938345E-05"
        iyy="0.00561040931161564"
        iyz="-1.07433119929774E-06"
        izz="0.00533913204176968" />
    </inertial>
    <visual>
      <origin
        xyz="0 0 0"
        rpy="0 0 0" />
      <geometry>
        <mesh
          filename="package://Assem1/meshes/Trunk_Link.STL" />
      </geometry>
      <material
        name="">
        <color
          rgba="1 1 1 1" />
      </material>
    </visual>
    <collision>
      <origin
        xyz="0 0 0"
        rpy="0 0 0" />
      <geometry>
        <mesh
          filename="package://Assem1/meshes/Trunk_Link.STL" />
      </geometry>
    </collision>
  </link>
  <joint
    name="Trunk_Joint"
    type="revolute">
    <origin
      xyz="0 0 0"
      rpy="0 0 0" />
    <parent
      link="Chassis_Link" />
    <child
      link="Trunk_Link" />
    <axis
      xyz="0 0 1" />
    <limit
      lower="0"
      upper="0.87266"
      effort="0"
      velocity="0" />
  </joint>
  <link
    name="Caster_Link">
    <inertial>
      <origin
        xyz="-0.472647441390191 0.0789496187119673 -0.0328685285624268"
        rpy="0 0 0" />
      <mass
        value="0.422184039657028" />
      <inertia
        ixx="0.000320826217154303"
        ixy="4.20879745539875E-05"
        ixz="7.16279846938345E-05"
        iyy="0.00561040931161564"
        iyz="-1.07433119929774E-06"
        izz="0.00533913204176968" />
    </inertial>
    <visual>
      <origin
        xyz="0 0 0"
        rpy="0 0 0" />
      <geometry>
        <mesh
          filename="package://Assem1/meshes/Caster_Link.STL" />
      </geometry>
      <material
        name="">
        <color
          rgba="0.792156862745098 0.819607843137255 0.933333333333333 1" />
      </material>
    </visual>
    <collision>
      <origin
        xyz="0 0 0"
        rpy="0 0 0" />
      <geometry>
        <mesh
          filename="package://Assem1/meshes/Caster_Link.STL" />
      </geometry>
    </collision>
  </link>
  <joint
    name="Caster_Joint"
    type="revolute">
    <origin
      xyz="0.29739 0.065985 0.14011"
      rpy="-1.5708 0.61087 -3.1416" />
    <parent
      link="base_link" />
    <child
      link="Caster_Link" />
    <axis
      xyz="0 0 0" />
    <limit
      lower="0"
      upper="0"
      effort="0"
      velocity="0" />
  </joint>
</robot>